Workbook
Name igenylo_neve: #REF!

Sheet Kitöltési útmutató
A1: KEHOP Plusz-4.1.7-24 OTTHONFELÚJÍTÁSI PROGRAM
A2: KÖLTSÉGVETÉS ÉS NYILATKOZATOK
A3: Hatályos: | B3: 2025. 10. 15-től
A4: A Költségvetés és nyilatkozatok dokumentum a Kölcsönkérelem szerves részét képezi, ezért kérjük, hogy annak kitöltésekor körültekintően járjon el. A kitöltés megkezdése előtt javasoljuk, hogy gondolja át az energetikai korszerűsítés pontos megvalósítását, vagyis, hogy mely elemeket fogja vállalkozóval végeztetni és mely alapanyagokat szerzi be saját maga. Fontos, hogy a táblázatokat elektronikusan, a munkalapok sorrendjében haladva töltse ki! A cellák kitöltése során amennyiben narancssárga színnel jelölt hibát észlel, úgy előbb javítsa a hibát és utána lépjen tovább a következő munkalapra. Kérjük a Kölcsönkérelem benyújtásakor ezen dokumentum minden releváns munkalapját kinyomtatva és aláírva hozza magával.
B5: Kizárólag ezen színnel kiemelt mezők kitöltését várjuk. Amint kitölti a megjelölt mezőt, a cella színe fehérre vált.
B6: Ezen mezőket ne töltse ki! A vállalkozási szerződésben és a saját beszerzés táblázatában lehetnek ilyen jelölésű mezők, amennyiben a 01_Költségvetés lapon nem jelölte az adott megvalósítandó fejlesztést vagy a 03_Saját beszerzésnél nem írhat az adott cellába (pl. korszerűsítési munkadíj vagy az előkészítés költségeinél anyagköltség)
A7: Kérjük, hogy az excelben minden szükséges értéket gépeljen be, ne másolással töltse ki. Amenyiben másolással tölti ki az adatokat, az működési problémákhoz vezethet
A8: 01_KÖLTSÉGVETÉS
A9: Figyelem! Minden itt megadott alapadat átvezetésre kerül a további munkalapokra, ezért minden esetben ezen munkalap kitöltésével kezdjen!
A10: I. Alapadatok
A11: Kölcsönigénylő neve: | B11: Gépelje be személyazonosító okmányán szereplő teljes nevét!
A12: Megvalósítási helyszín pontos címe: | B12: Kérjük, hogy pontos címet írjon be! Irányítószám, helység, közterület neve, közterület típusa, házszám, emelet, ajtó. Helyrajzi szám megadása kötelező, ha nincs természetbeni címe az ingatlannak.
A13: A fejlesztéssel érintett ingatlan típusa: | B13: Válassza ki a legördülő menüből a megfelelő opciót! (A legördülő menü elérése: kattintson/lépjen a cellára, s az ekkor - a cella mellett a lenyíló ablakból válassza ki a megfelelő lehetőséget!)
A14: II. Megvalósítandó fejlesztések
A15: Energiahatékonyság javításra vonatkozó tevékenységek: | B15: Minden tevékenység (pl. Hőszigetelés, Nyílászáró csere,… stb.) melletti cellában válassza ki a legördülő menüből, hogy milyen tevékenység(ek)et fog megvalósítani a fejlesztés során! Fontos, hogy minden tevékenység alatti mezőt töltsön ki (igen/nem). A tábla figyelmeztető jelzést ír ki, amennyiben a projekt árnyékoló mellett nem tartalmaz szigetelést vagy nyílászáró felújítást.
A16: Költségvetés | B16: A táblázat adatai a kitöltött vállalkozási szerződés(ek)ből és amennyiben releváns, úgy a saját beszerzés munkalapról emelik át az adatokat, ezért itt további adatot nem szükséges megadni. A táblázat kitöltése akkor tekinthető teljesnek, amikor a 02-es és a 03-as munkafüzetlapok is teljeskörűen kitöltésre kerülnek, tehát több vállalkozó esetén ugyanabban a dokumentumban kitöltésre kerülnek a korszerűsítés költségvetését érintő összegek.
B17: Kérjük adja meg minden, a korszerűsítés szempontjából releváns sor esetében a négyzetméter mennyiségeket. Fontos, hogy minden korszerűsítési tevékenység esetében vizsgálja meg, hogy a vállalkozási szerződésekben megadott négyzetméterek összege nem haladhatja meg az itt megadott mennyiséget. Amennyiben egy korszerűsítési munkálatot egynél több vállalkozó végez, akkor kiemelt figyelemmel adja meg a négyzetméter mennyiséget. (pl. ha a korszerűsítést két kivitelező végzi ugyanazon a területen - más-más tevékenység vonatkozásában -, akkor a vállakozási szerződések négyzetméter mennyiségei nem összegezhetőek).
B18: A mennyiségi (négyzetméter) adatok megadása után kiszámításra kerül az elszámolható költségek mértéke, azaz kitöltésre kerülnek a hitelprogramban elszámolható költségek a Felhívásban megadott fajlagos költséghatárig, s a fajlagos költséghatáron felüli összegek az el nem számolható költségek megfelelő sorában adódnak össze. Felhívjuk a figyelmét, hogy a fajlagos költséghatáron felüli költségek elszámolható összegének számításakor (amennyiben a nényzetméter nem kerek szám) a kerekítésből adódó összegzési hibák kiküszöbölése érdekében egész számokra való lekerekítési módszert használunk. Kérjük, hogy a számlákkal való elszámoláskor a számlazáradékolásánál is vegye ezt figyelembe és csak az elszámolható költség erejéig záradékolja a számlát.
A19: III. Nyilatkozatok
A20: Nyilatkozatok | B20: Kérjük, nyilatkozzon a felsorolt állítások kapcsán a legördülő menüben az "Igen"," Nem", illetve a "Nem releváns" válasz megjelölésével.
A21: Keltezés, aláírás, tanúzás | B21: Kérjük, a teljes kitöltést követően írja alá a kinyomtatott dokumentumot. Felhívjuk a figyelmét, hogy csak akkor nyomtassa ki a dokumentumot, ha a vállalkozási szerződés(ek) és saját beszerzés esetén a 03-as munkafüzetlap is kitöltésre került.
A22: 02_VÁLLALKOZÁSI SZERZŐDÉS
A23: Ez a munkalap tartalmazza a kivitelezővel megkötésre kerülő szerződés szövegét. Amennyiben több kivitelezőt vesz igénybe a projekt megvalósítása folyamán, úgy minden kivitelező esetén külön munkalapot töltsön ki a szerződésmintából. A vállalkozási szerződés műszaki tartalmában szereplő költségvetési adatok automatikusan átemelésre kerülnek a 01_Költségvetés munkalapra. Amennyiben több kivitelező érintett a projekben, úgy az egyes kitöltött vállalkozási szerződések költségvetési adatai összeadódnak a Költségvetés munkalapon - kivéve a négyzetméter adatok. A programban kizárólag ezen szerződésminta kitöltésével lehet igényelni a finanszírozási összeget.
A24: Alapadatok | B24: Töltse ki a szerződő felek adatait a Megrendelő és Vállalkozó részéről. A Megrendelő kizárólag a kölcsönügyletben adósként szereplő személy lehet, ezért a Megrendelő neve adat automatikusan töltődik a 01_Költségvetés munkalapról.
A25: A szerződés tárgya | B25: A megvalósítási helyszín adatát a Költségvetés munkalapról automatikusan átemeli a cella. A felújítási munkák teljesítésének a határideje az a nap, amikor az utolsó munkálat is elvégzésre kerül.
A26: Vállalkozási díj | B26: A vállalkozási díj nettó, ÁFA és bruttó összegét a szerződés I. számú mellékletben szereplő költségvetés összesített soraiból emelik át automatikusan a cellák.
A27: Munkavégzés ütemezése, határidők, fizetési feltételek | B27: Rögzítse a kivitelezés várható ütemezését, illetve hogy a kivitelező előlegbekérő/díjbekérő alapján kívánja-e a szerződéses összeg egy részét számlázni.
A28: Keltezés, aláírás, tanúzás | B28: Kérjük a teljes kitöltést követően írja alá a kinyomtatott dokumentumot.
A29: Műszaki tartalom
A30: Rögzítse minden - a kivitelező közreműködésével megvalósuló - tevékenységhez a m2 mennyiségeket, valamint a Nettó és a Bruttó elszámolható költségek összegét megbontva Anyagköltségre és Munkadíjra. A táblázat a rögzített adatok alapján automatikusan számolni fogja a Bruttó fajlagos költségeket (egységárakat) a megadott mennyiségekre vonatkoztatva. Amennyiben valamely költség meghaladja a Felhívásban megadott maximális fajlagos költséget, úgy a cella narancssárga színűre vált. A nem elszámolható költségek közé tudja rögzíteni azon tevékenységeket, melyeket szintén ezen kivitelező végez el a szerződés keretében és hozzájárulnak a minimum elvárt primerenergia megtakarításhoz. Minden ezen műszaki tartalom mellékletben szereplő adat automatikusan átemelésre kerül a 01_Költségvetés munkalap vonatkozó sorára.
A31: Használati melegvíz rendszerek | B31: Rögzítse a nettó és bruttó költségeket az Anyagköltségre és a Munkadíjra vonatkozóan. A táblázat vizsgálni fogja a fajlagos költség határokat.
A32: Határoló szerkezetek hőszigetelése | B32: Adja meg m2-ben a szigetelni kívánt felületek területét típusonként. Írja be a mennyiségekhez tartozó Nettó és Bruttó elszámolható költséget megbontva Anyagköltségre és Munkadíjra!
A33: Nyílászáró csere | B33: Rögzítse a nyílászáró korszerűsítés esetében típusonként a m2 adatokat, majd a nettó és bruttó költségeket az Anyagra és a Munkadíjra vonatkozóan.
A34: Fűtéskorszerűsítés | B34: Rögzítse a nettó és bruttó költségeket az Anyagköltségre és a Munkadíjra vonatkozóan.
A35: A projekt megvalósításához szükséges engedélyek megnevezése | B35: Itt szükséges megadni a megvalósításhoz szükséges hatósági és egyéb engedélyeket (pl: bővítés esetén építési engedély) a kivitelező által, melyet később a Kölcsönigénylőnek szükséges átvezetnie a kölcsönkérelmi nyomtatványba is.
A36: Kivitelezői nyilatkozat | B36: Minden nyilatkozat végén válassza ki a legördülő menüből a kivitelező a megfelelő választ a beruházás tartalmára, az árajánlatra, a megvalósítási helyszínére és a beépítendő eszközökre vonatkozóan. Hibaüzenet jelzi, amennyiben olyan választ ad a kérdésre, amivel a "Nem" válasszal a kölcsönkérelem nem nyújtható be.
A37: 03_Saját beszerzés
A38: Ezen munkalapon szükséges rögzíteni azokat az előkészítés költségeit, az egyéb költségeket és az olyan alapanyag beszerzéseket, melyek nem a kivitelezőn keresztül történnek, de a projekt részét képezik. Fontos, hogy egy típusú tevékenységez csak akkor tartozhat alapanyag beszerzés, amennyiben ahhoz valamely vállalkozási szerződés munkalapon munkadíj is kapcsolódik.
A39: A 01_Költségvetés oldalon megadott m2 mennyiség automatikusan átemelődik a Saját beszerzés munkalapra is, tehát a korszerűsítéssel érintett terület nagyságát ott szükséges megadnia, amelyhez az anyagokat beszerzi és amelyhez a vállalkozó munkadíja kapcsolódik.
A40: Kölcsönigénylő neve és megvalósítási helyszín | B40: Ezen adatok automatikusan kerülnek átemelésre a Költségvetés munkalapról.
...

Sheet 01_Költségvetés
G1: KEHOP Plusz-4.1.7-24 Otthonfelújítási Hitelprogram
M2: ML153U sz. melléklet
M3: Hatályos: | N3: 2025.10.15-től
B4: I. Alapadatok | I4: II. Megvalósítandó fejlesztések | P4: =IF(OR(ISBLANK(N6),ISBLANK(N7),ISBLANK(N5),ISBLANK(N8)),"Kérjük minden tevékenység vonatkozásában válaszoljon!","") -> Kérjük minden tevékenység vonatkozásában válaszoljon!
B5: Kölcsönigénylő neve: | I5: Használati melegvíz-rendszerek korszerűsítése | O5: =IF(OR(ISBLANK(N6),ISBLANK(N7),ISBLANK(N5),ISBLANK(N8)),"Kérjük minden tevékenység vonatkozásában válaszoljon!","") -> Kérjük minden tevékenység vonatkozásában válaszoljon!
B6: Megvalósítási helyszín pontos címe | I6: Határoló szerkezetek hőszigetelése
B7: A fejlesztéssel érintett ingatlan típusa | I7: Nyílászáró csere | O7: =IF(AND(XFD48>0,AND(XFD44=0,O21=0)),"Külső árnyékolók önállóan nem támogathatók!","")
I8: Fűtéskorszerűsítés (levegő-víz hőszivattyú, hőleadók, szekunder fűtési kör, padló- és mennyezethűtési/fűtési rendszerek, automatikus központi és helyi szabályozók)
B10: Megnevezés | E10: Mennyiség | F10: Mérték-egység | G10: Anyagköltség | I10: Munkadíj | K10: Bruttó költség összesen | M10: A korszerűsítés elszámolható költségei | P10: Elszámolható maximális fajlagos költségek
G11: Nettó | H11: Bruttó | I11: Nettó | J11: Bruttó | M11: Anyagköltség | N11: Munkadíj | O11: Összesen | P11: Anyagkts. | Q11: Munkadíj
B12: A. Előkészítés költségei | C12: A1 Kötelező előzetes tanulmányok, műszaki dokumentáció (energetikai tanúsítvány) | I12: =+'03_Saját beszerzés'!I9 -> 0 | J12: =+'03_Saját beszerzés'!J9 -> 0 | K12: =+J12 -> 0 | L12: =SUM(K12:K14) -> 0 | N12: =IF(ISBLANK(J12),,IF(K12>Q12,Q12,K12)) -> 0 | O12: =SUM(N12:N14) -> 0 | Q12: 115000 | S12: =IF(K12>Q12,K12-N12,0) -> 0
C13: A2 Engedélyezési dokumentumok, műszaki tervek, kiviteli és tendertervek és ezek hatósági díja | I13: =+'03_Saját beszerzés'!I10 -> 0 | J13: =+'03_Saját beszerzés'!J10 -> 0 | K13: =+J13 -> 0 | N13: =MIN(IF(L12>Q13,Q13-N12,K13+K14),K13+K14) -> 0 | Q13: 450000 | S13: =+K13+K14-N13 -> 0
C14: A4 Eljárási költségek | I14: =+'03_Saját beszerzés'!I11 -> 0 | J14: =+'03_Saját beszerzés'!J11 -> 0 | K14: =+J14 -> 0 | Q14: 450000
B15: B. Beruházások | K15: =SUM(K17:K55) -> 0 | M15: =SUM(M17:M55) -> 0 | N15: =SUM(N17:N55) -> 0 | O15: =+N15+M15 -> 0
B16: B1. Energiahatékonyság javítására vonatkozó tevékenységek | K16: =SUM(K17:K55) -> 0 | M16: =SUM(M17:M55) -> 0 | N16: =SUM(N17:N55) -> 0 | O16: =+N16+M16 -> 0
B17: B1b. Használati melegvíz rendszerek | C17: Használati melegvíz előállító berendezés | G17: ='02_Vállalkozási szerződés1'!G46+'02_Vállalkozási szerződés2 '!G47+'02_Vállalkozási szerződés3'!G47+'02_Vállalkozási szerződés4'!G47+'03_Saját beszerzés'!G14 -> 0 | H17: ='02_Vállalkozási szerződés1'!H46+'02_Vállalkozási szerződés2 '!H47+'02_Vállalkozási szerződés3'!H47+'02_Vállalkozási szerződés4'!H47+'03_Saját beszerzés'!H14 -> 0 | I17: ='02_Vállalkozási szerződés1'!I46+'02_Vállalkozási szerződés2 '!I47+'02_Vállalkozási szerződés3'!I47+'02_Vállalkozási szerződés4'!I47 -> 0 | J17: ='02_Vállalkozási szerződés1'!J46+'02_Vállalkozási szerződés2 '!J47+'02_Vállalkozási szerződés3'!J47+'02_Vállalkozási szerződés4'!J47 -> 0 | K17: =IFERROR(H17+J17,) -> 0 | L17: =SUM(K17:K20) -> 0 | M17: =IF(H17>P17,P17,H17) -> 0 | N17: =IF(J17>Q17,Q17,J17) -> 0 | O17: =SUM(M17:N20) -> 0 | P17: 266700 | Q17: 457200 | S17: =IF(K17>M17+Q17,+K17-M17-N17,0) -> 0
C18: Hőszivattyús használati melegvíz előállító és tároló berendezés felszerelés | G18: ='02_Vállalkozási szerződés1'!G47+'02_Vállalkozási szerződés2 '!G48+'02_Vállalkozási szerződés3'!G48+'02_Vállalkozási szerződés4'!G48+'03_Saját beszerzés'!G15 -> 0 | H18: ='02_Vállalkozási szerződés1'!H47+'02_Vállalkozási szerződés2 '!H48+'02_Vállalkozási szerződés3'!H48+'02_Vállalkozási szerződés4'!H48+'03_Saját beszerzés'!H15 -> 0 | I18: ='02_Vállalkozási szerződés1'!I47+'02_Vállalkozási szerződés2 '!I48+'02_Vállalkozási szerződés3'!I48+'02_Vállalkozási szerződés4'!I48 -> 0 | J18: ='02_Vállalkozási szerződés1'!J47+'02_Vállalkozási szerződés2 '!J48+'02_Vállalkozási szerződés3'!J48+'02_Vállalkozási szerződés4'!J48 -> 0 | K18: =IFERROR(H18+J18,) -> 0 | M18: =IF(H18>P18,P18,H18) -> 0 | N18: =IF(J18>Q18,Q18,J18) -> 0 | P18: 533400 | Q18: 254000 | S18: =IF(K18>M18+Q18,+K18-M18-N18,0) -> 0
C19: Használati melegvizet előállító napkollektor telepítése | D19: síkkollektor | F19: m2 | G19: ='02_Vállalkozási szerződés1'!G48+'02_Vállalkozási szerződés2 '!G49+'02_Vállalkozási szerződés3'!G49+'02_Vállalkozási szerződés4'!G49+'03_Saját beszerzés'!G16 -> 0 | H19: ='02_Vállalkozási szerződés1'!H48+'02_Vállalkozási szerződés2 '!H49+'02_Vállalkozási szerződés3'!H49+'02_Vállalkozási szerződés4'!H49+'03_Saját beszerzés'!H16 -> 0 | I19: ='02_Vállalkozási szerződés1'!I48+'02_Vállalkozási szerződés2 '!I49+'02_Vállalkozási szerződés3'!I49+'02_Vállalkozási szerződés4'!I49 -> 0 | J19: ='02_Vállalkozási szerződés1'!J48+'02_Vállalkozási szerződés2 '!J49+'02_Vállalkozási szerződés3'!J49+'02_Vállalkozási szerződés4'!J49 -> 0 | K19: =IFERROR(H19+J19,) -> 0 | M19: =IF(E19=0,,IF(H19/E19>P19,INT(E19*P19),H19)) -> 0 | N19: =IF(E19=0,,IF(J19/E19>Q19,INT(Q19*E19),J19)) -> 0 | P19: 131585 | Q19: 26515 | S19: =IF(ISBLANK(E19),0,IF(K19>M19+Q19,+K19-M19-N19,0)) -> 0
D20: vákuumcsöves kollektor | F20: m2 | G20: ='02_Vállalkozási szerződés1'!G49+'02_Vállalkozási szerződés2 '!G50+'02_Vállalkozási szerződés3'!G50+'02_Vállalkozási szerződés4'!G50+'03_Saját beszerzés'!G17 -> 0 | H20: ='02_Vállalkozási szerződés1'!H49+'02_Vállalkozási szerződés2 '!H50+'02_Vállalkozási szerződés3'!H50+'02_Vállalkozási szerződés4'!H50+'03_Saját beszerzés'!H17 -> 0 | I20: ='02_Vállalkozási szerződés1'!I49+'02_Vállalkozási szerződés2 '!I50+'02_Vállalkozási szerződés3'!I50+'02_Vállalkozási szerződés4'!I50 -> 0 | J20: ='02_Vállalkozási szerződés1'!J49+'02_Vállalkozási szerződés2 '!J50+'02_Vállalkozási szerződés3'!J50+'02_Vállalkozási szerződés4'!J50 -> 0 | K20: =IFERROR(H20+J20,) -> 0 | M20: =IF(E20=0,,IF(H20/E20>P20,INT(E20*P20),H20)) -> 0 | N20: =IF(E20=0,,IF(J20/E20>Q20,INT(Q20*E20),J20)) -> 0 | P20: 159874 | Q20: 26515 | S20: =IF(ISBLANK(E20),0,IF(K20>M20+Q20,+K20-M20-N20,0)) -> 0
B21: B1c. Határoló szerkezetek hőszigetelése | C21: Homlokzat EPS és lábazati XPS | D21: -12 cm-ig | F21: m2 | G21: ='02_Vállalkozási szerződés1'!G50+'02_Vállalkozási szerződés2 '!G51+'02_Vállalkozási szerződés3'!G51+'02_Vállalkozási szerződés4'!G51+'03_Saját beszerzés'!G18 -> 0 | H21: ='02_Vállalkozási szerződés1'!H50+'02_Vállalkozási szerződés2 '!H51+'02_Vállalkozási szerződés3'!H51+'02_Vállalkozási szerződés4'!H51+'03_Saját beszerzés'!H18 -> 0 | I21: ='02_Vállalkozási szerződés1'!I50+'02_Vállalkozási szerződés2 '!I51+'02_Vállalkozási szerződés3'!I51+'02_Vállalkozási szerződés4'!I51 -> 0 | J21: ='02_Vállalkozási szerződés1'!J50+'02_Vállalkozási szerződés2 '!J51+'02_Vállalkozási szerződés3'!J51+'02_Vállalkozási szerződés4'!J51 -> 0 | K21: =IFERROR(H21+J21,) -> 0 | L21: =SUM(K21:K43) -> 0 | M21: =IF(E21=0,,IF(H21/E21>P21,INT(E21*P21),H21)) -> 0 | N21: =IF(E21=0,,IF(J21/E21>Q21,INT(Q21*E21),J21)) -> 0 | O21: =SUM(M21:N43) -> 0 | P21: 25838 | Q21: 25220 | S21: =IF(ISBLANK(E21),0,IF(K21>M21+Q21,+K21-M21-N21,0)) -> 0
D22: 13-15 cm | F22: m2 | G22: ='02_Vállalkozási szerződés1'!G51+'02_Vállalkozási szerződés2 '!G52+'02_Vállalkozási szerződés3'!G52+'02_Vállalkozási szerződés4'!G52+'03_Saját beszerzés'!G19 -> 0 | H22: ='02_Vállalkozási szerződés1'!H51+'02_Vállalkozási szerződés2 '!H52+'02_Vállalkozási szerződés3'!H52+'02_Vállalkozási szerződés4'!H52+'03_Saját beszerzés'!H19 -> 0 | I22: ='02_Vállalkozási szerződés1'!I51+'02_Vállalkozási szerződés2 '!I52+'02_Vállalkozási szerződés3'!I52+'02_Vállalkozási szerződés4'!I52 -> 0 | J22: ='02_Vállalkozási szerződés1'!J51+'02_Vállalkozási szerződés2 '!J52+'02_Vállalkozási szerződés3'!J52+'02_Vállalkozási szerződés4'!J52 -> 0 | K22: =IFERROR(H22+J22,) -> 0 | M22: =IF(E22=0,,IF(H22/E22>P22,INT(E22*P22),H22)) -> 0 | N22: =IF(E22=0,,IF(J22/E22>Q22,INT(Q22*E22),J22)) -> 0 | P22: 27414 | Q22: 25220 | S22: =IF(ISBLANK(E22),0,IF(K22>M22+Q22,+K22-M22-N22,0)) -> 0
D23: 16-20 cm | F23: m2 | G23: ='02_Vállalkozási szerződés1'!G52+'02_Vállalkozási szerződés2 '!G53+'02_Vállalkozási szerződés3'!G53+'02_Vállalkozási szerződés4'!G53+'03_Saját beszerzés'!G20 -> 0 | H23: ='02_Vállalkozási szerződés1'!H52+'02_Vállalkozási szerződés2 '!H53+'02_Vállalkozási szerződés3'!H53+'02_Vállalkozási szerződés4'!H53+'03_Saját beszerzés'!H20 -> 0 | I23: ='02_Vállalkozási szerződés1'!I52+'02_Vállalkozási szerződés2 '!I53+'02_Vállalkozási szerződés3'!I53+'02_Vállalkozási szerződés4'!I53 -> 0 | J23: ='02_Vállalkozási szerződés1'!J52+'02_Vállalkozási szerződés2 '!J53+'02_Vállalkozási szerződés3'!J53+'02_Vállalkozási szerződés4'!J53 -> 0 | K23: =IFERROR(H23+J23,) -> 0 | M23: =IF(E23=0,,IF(H23/E23>P23,INT(E23*P23),H23)) -> 0 | N23: =IF(E23=0,,IF(J23/E23>Q23,INT(Q23*E23),J23)) -> 0 | P23: 30565 | Q23: 25220 | S23: =IF(ISBLANK(E23),0,IF(K23>M23+Q23,+K23-M23-N23,0)) -> 0
C24: Homlokzat kőzetgyapot és lábazati XPS | D24: -12 cm-ig | F24: m2 | G24: ='02_Vállalkozási szerződés1'!G53+'02_Vállalkozási szerződés2 '!G54+'02_Vállalkozási szerződés3'!G54+'02_Vállalkozási szerződés4'!G54+'03_Saját beszerzés'!G21 -> 0 | H24: ='02_Vállalkozási szerződés1'!H53+'02_Vállalkozási szerződés2 '!H54+'02_Vállalkozási szerződés3'!H54+'02_Vállalkozási szerződés4'!H54+'03_Saját beszerzés'!H21 -> 0 | I24: ='02_Vállalkozási szerződés1'!I53+'02_Vállalkozási szerződés2 '!I54+'02_Vállalkozási szerződés3'!I54+'02_Vállalkozási szerződés4'!I54 -> 0 | J24: ='02_Vállalkozási szerződés1'!J53+'02_Vállalkozási szerződés2 '!J54+'02_Vállalkozási szerződés3'!J54+'02_Vállalkozási szerződés4'!J54 -> 0 | K24: =IFERROR(H24+J24,) -> 0 | M24: =IF(E24=0,,IF(H24/E24>P24,INT(E24*P24),H24)) -> 0 | N24: =IF(E24=0,,IF(J24/E24>Q24,INT(Q24*E24),J24)) -> 0 | P24: 27767 | Q24: 25220 | S24: =IF(ISBLANK(E24),0,IF(K24>M24+Q24,+K24-M24-N24,0)) -> 0
D25: 13-15 cm | F25: m2 | G25: ='02_Vállalkozási szerződés1'!G54+'02_Vállalkozási szerződés2 '!G55+'02_Vállalkozási szerződés3'!G55+'02_Vállalkozási szerződés4'!G55+'03_Saját beszerzés'!G22 -> 0 | H25: ='02_Vállalkozási szerződés1'!H54+'02_Vállalkozási szerződés2 '!H55+'02_Vállalkozási szerződés3'!H55+'02_Vállalkozási szerződés4'!H55+'03_Saját beszerzés'!H22 -> 0 | I25: ='02_Vállalkozási szerződés1'!I54+'02_Vállalkozási szerződés2 '!I55+'02_Vállalkozási szerződés3'!I55+'02_Vállalkozási szerződés4'!I55 -> 0 | J25: ='02_Vállalkozási szerződés1'!J54+'02_Vállalkozási szerződés2 '!J55+'02_Vállalkozási szerződés3'!J55+'02_Vállalkozási szerződés4'!J55 -> 0 | K25: =IFERROR(H25+J25,) -> 0 | M25: =IF(E25=0,,IF(H25/E25>P25,INT(E25*P25),H25)) -> 0 | N25: =IF(E25=0,,IF(J25/E25>Q25,INT(Q25*E25),J25)) -> 0 | P25: 30307 | Q25: 25220 | S25: =IF(ISBLANK(E25),0,IF(K25>M25+Q25,+K25-M25-N25,0)) -> 0
D26: 16-20 cm | F26: m2 | G26: ='02_Vállalkozási szerződés1'!G55+'02_Vállalkozási szerződés2 '!G56+'02_Vállalkozási szerződés3'!G56+'02_Vállalkozási szerződés4'!G56+'03_Saját beszerzés'!G23 -> 0 | H26: ='02_Vállalkozási szerződés1'!H55+'02_Vállalkozási szerződés2 '!H56+'02_Vállalkozási szerződés3'!H56+'02_Vállalkozási szerződés4'!H56+'03_Saját beszerzés'!H23 -> 0 | I26: ='02_Vállalkozási szerződés1'!I55+'02_Vállalkozási szerződés2 '!I56+'02_Vállalkozási szerződés3'!I56+'02_Vállalkozási szerződés4'!I56 -> 0 | J26: ='02_Vállalkozási szerződés1'!J55+'02_Vállalkozási szerződés2 '!J56+'02_Vállalkozási szerződés3'!J56+'02_Vállalkozási szerződés4'!J56 -> 0 | K26: =IFERROR(H26+J26,) -> 0 | M26: =IF(E26=0,,IF(H26/E26>P26,INT(E26*P26),H26)) -> 0 | N26: =IF(E26=0,,IF(J26/E26>Q26,INT(Q26*E26),J26)) -> 0 | P26: 34422 | Q26: 25220 | S26: =IF(ISBLANK(E26),0,IF(K26>M26+Q26,+K26-M26-N26,0)) -> 0
C27: Homlokzat PIR és lábazati XPS | D27: -12 cm-ig | F27: m2 | G27: ='02_Vállalkozási szerződés1'!G56+'02_Vállalkozási szerződés2 '!G57+'02_Vállalkozási szerződés3'!G57+'02_Vállalkozási szerződés4'!G57+'03_Saját beszerzés'!G24 -> 0 | H27: ='02_Vállalkozási szerződés1'!H56+'02_Vállalkozási szerződés2 '!H57+'02_Vállalkozási szerződés3'!H57+'02_Vállalkozási szerződés4'!H57+'03_Saját beszerzés'!H24 -> 0 | I27: ='02_Vállalkozási szerződés1'!I56+'02_Vállalkozási szerződés2 '!I57+'02_Vállalkozási szerződés3'!I57+'02_Vállalkozási szerződés4'!I57 -> 0 | J27: ='02_Vállalkozási szerződés1'!J56+'02_Vállalkozási szerződés2 '!J57+'02_Vállalkozási szerződés3'!J57+'02_Vállalkozási szerződés4'!J57 -> 0 | K27: =IFERROR(H27+J27,) -> 0 | M27: =IF(E27=0,,IF(H27/E27>P27,INT(E27*P27),H27)) -> 0 | N27: =IF(E27=0,,IF(J27/E27>Q27,INT(Q27*E27),J27)) -> 0 | P27: 31942 | Q27: 25220 | S27: =IF(ISBLANK(E27),0,IF(K27>M27+Q27,+K27-M27-N27,0)) -> 0
D28: 13-15 cm | F28: m2 | G28: ='02_Vállalkozási szerződés1'!G57+'02_Vállalkozási szerződés2 '!G58+'02_Vállalkozási szerződés3'!G58+'02_Vállalkozási szerződés4'!G58+'03_Saját beszerzés'!G25 -> 0 | H28: ='02_Vállalkozási szerződés1'!H57+'02_Vállalkozási szerződés2 '!H58+'02_Vállalkozási szerződés3'!H58+'02_Vállalkozási szerződés4'!H58+'03_Saját beszerzés'!H25 -> 0 | I28: ='02_Vállalkozási szerződés1'!I57+'02_Vállalkozási szerződés2 '!I58+'02_Vállalkozási szerződés3'!I58+'02_Vállalkozási szerződés4'!I58 -> 0 | J28: ='02_Vállalkozási szerződés1'!J57+'02_Vállalkozási szerződés2 '!J58+'02_Vállalkozási szerződés3'!J58+'02_Vállalkozási szerződés4'!J58 -> 0 | K28: =IFERROR(H28+J28,) -> 0 | M28: =IF(E28=0,,IF(H28/E28>P28,INT(E28*P28),H28)) -> 0 | N28: =IF(E28=0,,IF(J28/E28>Q28,INT(Q28*E28),J28)) -> 0 | P28: 35496 | Q28: 25220 | S28: =IF(ISBLANK(E28),0,IF(K28>M28+Q28,+K28-M28-N28,0)) -> 0
D29: 16-20 cm | F29: m2 | G29: ='02_Vállalkozási szerződés1'!G58+'02_Vállalkozási szerződés2 '!G59+'02_Vállalkozási szerződés3'!G59+'02_Vállalkozási szerződés4'!G59+'03_Saját beszerzés'!G26 -> 0 | H29: ='02_Vállalkozási szerződés1'!H58+'02_Vállalkozási szerződés2 '!H59+'02_Vállalkozási szerződés3'!H59+'02_Vállalkozási szerződés4'!H59+'03_Saját beszerzés'!H26 -> 0 | I29: ='02_Vállalkozási szerződés1'!I58+'02_Vállalkozási szerződés2 '!I59+'02_Vállalkozási szerződés3'!I59+'02_Vállalkozási szerződés4'!I59 -> 0 | J29: ='02_Vállalkozási szerződés1'!J58+'02_Vállalkozási szerződés2 '!J59+'02_Vállalkozási szerződés3'!J59+'02_Vállalkozási szerződés4'!J59 -> 0 | K29: =IFERROR(H29+J29,) -> 0 | M29: =IF(E29=0,,IF(H29/E29>P29,INT(E29*P29),H29)) -> 0 | N29: =IF(E29=0,,IF(J29/E29>Q29,INT(Q29*E29),J29)) -> 0 | P29: 41258 | Q29: 25220 | S29: =IF(ISBLANK(E29),0,IF(K29>M29+Q29,+K29-M29-N29,0)) -> 0
C30: Tetősík | D30: -20 cm-ig | F30: m2 | G30: ='02_Vállalkozási szerződés1'!G59+'02_Vállalkozási szerződés2 '!G60+'02_Vállalkozási szerződés3'!G60+'02_Vállalkozási szerződés4'!G60+'03_Saját beszerzés'!G27 -> 0 | H30: ='02_Vállalkozási szerződés1'!H59+'02_Vállalkozási szerződés2 '!H60+'02_Vállalkozási szerződés3'!H60+'02_Vállalkozási szerződés4'!H60+'03_Saját beszerzés'!H27 -> 0 | I30: ='02_Vállalkozási szerződés1'!I59+'02_Vállalkozási szerződés2 '!I60+'02_Vállalkozási szerződés3'!I60+'02_Vállalkozási szerződés4'!I60 -> 0 | J30: ='02_Vállalkozási szerződés1'!J59+'02_Vállalkozási szerződés2 '!J60+'02_Vállalkozási szerződés3'!J60+'02_Vállalkozási szerződés4'!J60 -> 0 | K30: =IFERROR(H30+J30,) -> 0 | M30: =IF(E30=0,,IF(H30/E30>P30,INT(E30*P30),H30)) -> 0 | N30: =IF(E30=0,,IF(J30/E30>Q30,INT(Q30*E30),J30)) -> 0 | P30: 17108 | Q30: 32296 | S30: =IF(ISBLANK(E30),0,IF(K30>M30+Q30,+K30-M30-N30,0)) -> 0
D31: 21-25 cm | F31: m2 | G31: ='02_Vállalkozási szerződés1'!G60+'02_Vállalkozási szerződés2 '!G61+'02_Vállalkozási szerződés3'!G61+'02_Vállalkozási szerződés4'!G61+'03_Saját beszerzés'!G28 -> 0 | H31: ='02_Vállalkozási szerződés1'!H60+'02_Vállalkozási szerződés2 '!H61+'02_Vállalkozási szerződés3'!H61+'02_Vállalkozási szerződés4'!H61+'03_Saját beszerzés'!H28 -> 0 | I31: ='02_Vállalkozási szerződés1'!I60+'02_Vállalkozási szerződés2 '!I61+'02_Vállalkozási szerződés3'!I61+'02_Vállalkozási szerződés4'!I61 -> 0 | J31: ='02_Vállalkozási szerződés1'!J60+'02_Vállalkozási szerződés2 '!J61+'02_Vállalkozási szerződés3'!J61+'02_Vállalkozási szerződés4'!J61 -> 0 | K31: =IFERROR(H31+J31,) -> 0 | M31: =IF(E31=0,,IF(H31/E31>P31,INT(E31*P31),H31)) -> 0 | N31: =IF(E31=0,,IF(J31/E31>Q31,INT(Q31*E31),J31)) -> 0 | P31: 18847 | Q31: 32296 | S31: =IF(ISBLANK(E31),0,IF(K31>M31+Q31,+K31-M31-N31,0)) -> 0
D32: 26-30 cm | F32: m2 | G32: ='02_Vállalkozási szerződés1'!G61+'02_Vállalkozási szerződés2 '!G62+'02_Vállalkozási szerződés3'!G62+'02_Vállalkozási szerződés4'!G62+'03_Saját beszerzés'!G29 -> 0 | H32: ='02_Vállalkozási szerződés1'!H61+'02_Vállalkozási szerződés2 '!H62+'02_Vállalkozási szerződés3'!H62+'02_Vállalkozási szerződés4'!H62+'03_Saját beszerzés'!H29 -> 0 | I32: ='02_Vállalkozási szerződés1'!I61+'02_Vállalkozási szerződés2 '!I62+'02_Vállalkozási szerződés3'!I62+'02_Vállalkozási szerződés4'!I62 -> 0 | J32: ='02_Vállalkozási szerződés1'!J61+'02_Vállalkozási szerződés2 '!J62+'02_Vállalkozási szerződés3'!J62+'02_Vállalkozási szerződés4'!J62 -> 0 | K32: =IFERROR(H32+J32,) -> 0 | M32: =IF(E32=0,,IF(H32/E32>P32,INT(E32*P32),H32)) -> 0 | N32: =IF(E32=0,,IF(J32/E32>Q32,INT(Q32*E32),J32)) -> 0 | P32: 21006 | Q32: 32296 | S32: =IF(ISBLANK(E32),0,IF(K32>M32+Q32,+K32-M32-N32,0)) -> 0
C33: Padlásfödém (kőzetgyapot) | D33: -30 cm-ig | F33: m2 | G33: ='02_Vállalkozási szerződés1'!G62+'02_Vállalkozási szerződés2 '!G63+'02_Vállalkozási szerződés3'!G63+'02_Vállalkozási szerződés4'!G63+'03_Saját beszerzés'!G30 -> 0 | H33: ='02_Vállalkozási szerződés1'!H62+'02_Vállalkozási szerződés2 '!H63+'02_Vállalkozási szerződés3'!H63+'02_Vállalkozási szerződés4'!H63+'03_Saját beszerzés'!H30 -> 0 | I33: ='02_Vállalkozási szerződés1'!I62+'02_Vállalkozási szerződés2 '!I63+'02_Vállalkozási szerződés3'!I63+'02_Vállalkozási szerződés4'!I63 -> 0 | J33: ='02_Vállalkozási szerződés1'!J62+'02_Vállalkozási szerződés2 '!J63+'02_Vállalkozási szerződés3'!J63+'02_Vállalkozási szerződés4'!J63 -> 0 | K33: =IFERROR(H33+J33,) -> 0 | M33: =IF(E33=0,,IF(H33/E33>P33,INT(E33*P33),H33)) -> 0 | N33: =IF(E33=0,,IF(J33/E33>Q33,INT(Q33*E33),J33)) -> 0 | P33: 11325 | Q33: 14878 | S33: =IF(ISBLANK(E33),0,IF(K33>M33+Q33,+K33-M33-N33,0)) -> 0
D34: 31-40 cm | F34: m2 | G34: ='02_Vállalkozási szerződés1'!G63+'02_Vállalkozási szerződés2 '!G64+'02_Vállalkozási szerződés3'!G64+'02_Vállalkozási szerződés4'!G64+'03_Saját beszerzés'!G31 -> 0 | H34: ='02_Vállalkozási szerződés1'!H63+'02_Vállalkozási szerződés2 '!H64+'02_Vállalkozási szerződés3'!H64+'02_Vállalkozási szerződés4'!H64+'03_Saját beszerzés'!H31 -> 0 | I34: ='02_Vállalkozási szerződés1'!I63+'02_Vállalkozási szerződés2 '!I64+'02_Vállalkozási szerződés3'!I64+'02_Vállalkozási szerződés4'!I64 -> 0 | J34: ='02_Vállalkozási szerződés1'!J63+'02_Vállalkozási szerződés2 '!J64+'02_Vállalkozási szerződés3'!J64+'02_Vállalkozási szerződés4'!J64 -> 0 | K34: =IFERROR(H34+J34,) -> 0 | M34: =IF(E34=0,,IF(H34/E34>P34,INT(E34*P34),H34)) -> 0 | N34: =IF(E34=0,,IF(J34/E34>Q34,INT(Q34*E34),J34)) -> 0 | P34: 13716 | Q34: 14878 | S34: =IF(ISBLANK(E34),0,IF(K34>M34+Q34,+K34-M34-N34,0)) -> 0
C35: Padlásfödém (üveggyapot) | D35: -30 cm-ig | F35: m2 | G35: ='02_Vállalkozási szerződés1'!G64+'02_Vállalkozási szerződés2 '!G65+'02_Vállalkozási szerződés3'!G65+'02_Vállalkozási szerződés4'!G65+'03_Saját beszerzés'!G32 -> 0 | H35: ='02_Vállalkozási szerződés1'!H64+'02_Vállalkozási szerződés2 '!H65+'02_Vállalkozási szerződés3'!H65+'02_Vállalkozási szerződés4'!H65+'03_Saját beszerzés'!H32 -> 0 | I35: ='02_Vállalkozási szerződés1'!I64+'02_Vállalkozási szerződés2 '!I65+'02_Vállalkozási szerződés3'!I65+'02_Vállalkozási szerződés4'!I65 -> 0 | J35: ='02_Vállalkozási szerződés1'!J64+'02_Vállalkozási szerződés2 '!J65+'02_Vállalkozási szerződés3'!J65+'02_Vállalkozási szerződés4'!J65 -> 0 | K35: =IFERROR(H35+J35,) -> 0 | M35: =IF(E35=0,,IF(H35/E35>P35,INT(E35*P35),H35)) -> 0 | N35: =IF(E35=0,,IF(J35/E35>Q35,INT(Q35*E35),J35)) -> 0 | P35: 10636 | Q35: 14878 | S35: =IF(ISBLANK(E35),0,IF(K35>M35+Q35,+K35-M35-N35,0)) -> 0
D36: 31-40 cm | F36: m2 | G36: ='02_Vállalkozási szerződés1'!G65+'02_Vállalkozási szerződés2 '!G66+'02_Vállalkozási szerződés3'!G66+'02_Vállalkozási szerződés4'!G66+'03_Saját beszerzés'!G33 -> 0 | H36: ='02_Vállalkozási szerződés1'!H65+'02_Vállalkozási szerződés2 '!H66+'02_Vállalkozási szerződés3'!H66+'02_Vállalkozási szerződés4'!H66+'03_Saját beszerzés'!H33 -> 0 | I36: ='02_Vállalkozási szerződés1'!I65+'02_Vállalkozási szerződés2 '!I66+'02_Vállalkozási szerződés3'!I66+'02_Vállalkozási szerződés4'!I66 -> 0 | J36: ='02_Vállalkozási szerződés1'!J65+'02_Vállalkozási szerződés2 '!J66+'02_Vállalkozási szerződés3'!J66+'02_Vállalkozási szerződés4'!J66 -> 0 | K36: =IFERROR(H36+J36,) -> 0 | M36: =IF(E36=0,,IF(H36/E36>P36,INT(E36*P36),H36)) -> 0 | N36: =IF(E36=0,,IF(J36/E36>Q36,INT(Q36*E36),J36)) -> 0 | P36: 13037 | Q36: 14878 | S36: =IF(ISBLANK(E36),0,IF(K36>M36+Q36,+K36-M36-N36,0)) -> 0
C37: Pincefödém | D37: -10 cm-ig | F37: m2 | G37: ='02_Vállalkozási szerződés1'!G66+'02_Vállalkozási szerződés2 '!G67+'02_Vállalkozási szerződés3'!G67+'02_Vállalkozási szerződés4'!G67+'03_Saját beszerzés'!G34 -> 0 | H37: ='02_Vállalkozási szerződés1'!H66+'02_Vállalkozási szerződés2 '!H67+'02_Vállalkozási szerződés3'!H67+'02_Vállalkozási szerződés4'!H67+'03_Saját beszerzés'!H34 -> 0 | I37: ='02_Vállalkozási szerződés1'!I66+'02_Vállalkozási szerződés2 '!I67+'02_Vállalkozási szerződés3'!I67+'02_Vállalkozási szerződés4'!I67 -> 0 | J37: ='02_Vállalkozási szerződés1'!J66+'02_Vállalkozási szerződés2 '!J67+'02_Vállalkozási szerződés3'!J67+'02_Vállalkozási szerződés4'!J67 -> 0 | K37: =IFERROR(H37+J37,) -> 0 | M37: =IF(E37=0,,IF(H37/E37>P37,INT(E37*P37),H37)) -> 0 | N37: =IF(E37=0,,IF(J37/E37>Q37,INT(Q37*E37),J37)) -> 0 | P37: 18382 | Q37: 6972 | S37: =IF(ISBLANK(E37),0,IF(K37>M37+Q37,+K37-M37-N37,0)) -> 0
D38: 11-15 cm | F38: m2 | G38: ='02_Vállalkozási szerződés1'!G67+'02_Vállalkozási szerződés2 '!G68+'02_Vállalkozási szerződés3'!G68+'02_Vállalkozási szerződés4'!G68+'03_Saját beszerzés'!G35 -> 0 | H38: ='02_Vállalkozási szerződés1'!H67+'02_Vállalkozási szerződés2 '!H68+'02_Vállalkozási szerződés3'!H68+'02_Vállalkozási szerződés4'!H68+'03_Saját beszerzés'!H35 -> 0 | I38: ='02_Vállalkozási szerződés1'!I67+'02_Vállalkozási szerződés2 '!I68+'02_Vállalkozási szerződés3'!I68+'02_Vállalkozási szerződés4'!I68 -> 0 | J38: ='02_Vállalkozási szerződés1'!J67+'02_Vállalkozási szerződés2 '!J68+'02_Vállalkozási szerződés3'!J68+'02_Vállalkozási szerződés4'!J68 -> 0 | K38: =IFERROR(H38+J38,) -> 0 | M38: =IF(E38=0,,IF(H38/E38>P38,INT(E38*P38),H38)) -> 0 | N38: =IF(E38=0,,IF(J38/E38>Q38,INT(Q38*E38),J38)) -> 0 | P38: 26256 | Q38: 6972 | S38: =IF(ISBLANK(E38),0,IF(K38>M38+Q38,+K38-M38-N38,0)) -> 0
C39: Árkád feletti alulról hűlő födém(kőzetgyapot) | D39: -12 cm-ig | F39: m2 | G39: ='02_Vállalkozási szerződés1'!G68+'02_Vállalkozási szerződés2 '!G69+'02_Vállalkozási szerződés3'!G69+'02_Vállalkozási szerződés4'!G69+'03_Saját beszerzés'!G36 -> 0 | H39: ='02_Vállalkozási szerződés1'!H68+'02_Vállalkozási szerződés2 '!H69+'02_Vállalkozási szerződés3'!H69+'02_Vállalkozási szerződés4'!H69+'03_Saját beszerzés'!H36 -> 0 | I39: ='02_Vállalkozási szerződés1'!I68+'02_Vállalkozási szerződés2 '!I69+'02_Vállalkozási szerződés3'!I69+'02_Vállalkozási szerződés4'!I69 -> 0 | J39: ='02_Vállalkozási szerződés1'!J68+'02_Vállalkozási szerződés2 '!J69+'02_Vállalkozási szerződés3'!J69+'02_Vállalkozási szerződés4'!J69 -> 0 | K39: =IFERROR(H39+J39,) -> 0 | M39: =IF(E39=0,,IF(H39/E39>P39,INT(E39*P39),H39)) -> 0 | N39: =IF(E39=0,,IF(J39/E39>Q39,INT(Q39*E39),J39)) -> 0 | P39: 24274 | Q39: 23813 | S39: =IF(ISBLANK(E39),0,IF(K39>M39+Q39,+K39-M39-N39,0)) -> 0
D40: 13-15 cm | F40: m2 | G40: ='02_Vállalkozási szerződés1'!G69+'02_Vállalkozási szerződés2 '!G70+'02_Vállalkozási szerződés3'!G70+'02_Vállalkozási szerződés4'!G70+'03_Saját beszerzés'!G37 -> 0 | H40: ='02_Vállalkozási szerződés1'!H69+'02_Vállalkozási szerződés2 '!H70+'02_Vállalkozási szerződés3'!H70+'02_Vállalkozási szerződés4'!H70+'03_Saját beszerzés'!H37 -> 0 | I40: ='02_Vállalkozási szerződés1'!I69+'02_Vállalkozási szerződés2 '!I70+'02_Vállalkozási szerződés3'!I70+'02_Vállalkozási szerződés4'!I70 -> 0 | J40: ='02_Vállalkozási szerződés1'!J69+'02_Vállalkozási szerződés2 '!J70+'02_Vállalkozási szerződés3'!J70+'02_Vállalkozási szerződés4'!J70 -> 0 | K40: =IFERROR(H40+J40,) -> 0 | M40: =IF(E40=0,,IF(H40/E40>P40,INT(E40*P40),H40)) -> 0 | N40: =IF(E40=0,,IF(J40/E40>Q40,INT(Q40*E40),J40)) -> 0 | P40: 25984 | Q40: 23813 | S40: =IF(ISBLANK(E40),0,IF(K40>M40+Q40,+K40-M40-N40,0)) -> 0
D41: 16-20 cm | F41: m2 | G41: ='02_Vállalkozási szerződés1'!G70+'02_Vállalkozási szerződés2 '!G71+'02_Vállalkozási szerződés3'!G71+'02_Vállalkozási szerződés4'!G71+'03_Saját beszerzés'!G38 -> 0 | H41: ='02_Vállalkozási szerződés1'!H70+'02_Vállalkozási szerződés2 '!H71+'02_Vállalkozási szerződés3'!H71+'02_Vállalkozási szerződés4'!H71+'03_Saját beszerzés'!H38 -> 0 | I41: ='02_Vállalkozási szerződés1'!I70+'02_Vállalkozási szerződés2 '!I71+'02_Vállalkozási szerződés3'!I71+'02_Vállalkozási szerződés4'!I71 -> 0 | J41: ='02_Vállalkozási szerződés1'!J70+'02_Vállalkozási szerződés2 '!J71+'02_Vállalkozási szerződés3'!J71+'02_Vállalkozási szerződés4'!J71 -> 0 | K41: =IFERROR(H41+J41,) -> 0 | M41: =IF(E41=0,,IF(H41/E41>P41,INT(E41*P41),H41)) -> 0 | N41: =IF(E41=0,,IF(J41/E41>Q41,INT(Q41*E41),J41)) -> 0 | P41: 28075 | Q41: 23813 | S41: =IF(ISBLANK(E41),0,IF(K41>M41+Q41,+K41-M41-N41,0)) -> 0
...

Sheet 02_Vállalkozási szerződés1
B1: Vállalkozási szerződés | K1: Hatályos: | L1: =+'01_Költségvetés'!N3 -> 2025.10.15-től
B2: a KEHOP Plusz-4.1.7-24 kódszámú Otthonfelújítási Program Lakossági energiahatékonysági beruházások megvalósításához igénybevételéhez
B3: amely létrejött egyrészről
B4: név: | E4: {=IF(ISBLANK('01_Költségvetés'!D5:D5),"",'01_Költségvetés'!D5:D5)}
B5: születési hely/idő:
B6: anyja neve:
B7: állandó lakcíme:
B8: (a továbbiakban: Megrendelő), másrészről
B9: cég/vállalkozó neve:
B10: cégjegyzékszám/egyéni vállalkozói nyilvántartási száma:
B11: székhelye:
B12: adószáma:
B13: képviseletében eljáró személy:
B14: mint vállalkozó (a továbbiakban: Vállalkozó),
B15: (a továbbiakban együtt: Felek) között a szerződés aláírásának napján, az alábbiak szerint:
B16: I. A szerződés tárgya:
B17: A „Otthonfelújítási Program - Lakossági energiahatékonysági beruházások megvalósításához” című (KEHOP Plusz 4.1.7-24 kódszámú) Felhíváshoz (a továbbiakban: Felhívás) kapcsolódó Európai Uniós forrású Lakossági Hitelprogramok Eljárási Rendjének (a továbbiakban Lakossági Eljárási Rend) keretében benyújtásra kerülő kölcsönkérelembe foglalt, jelen szerződésben részletezett műszaki tartalom hatályos jogszabályoknak megfelelő módon történő megvalósítása az alábbi ingatlanon:
B18: Az ingatlan címe: | E18: {=IF(ISBLANK('01_Költségvetés'!D6:D6),"",'01_Költségvetés'!D6:D6)}
B20: II. Műszaki tartalom:
B21: Jelen szerződés I. pontjában megjelölt ingatlan vonatkozásában a Megrendelő jelen szerződés alapján megrendeli a Vállalkozótól, a Vállalkozó pedig vállalja – a Lakossági Eljárási Rend alapján benyújtásra kerülő Felhívásban foglalt – a vállalkozói szerződés 1. számú mellékletében felsorolt műszaki tartalom megvalósítását. A Megrendelő kötelezettséget vállal a jelen szerződés alapján elvégzett munka átvételére és a vállalkozói díj megfizetésére. A Vállalkozói szerződés jelen pontjában rögzített táblázatban foglalt műszaki tartalommal, valamint a Lakossági Eljárási Rendben foglaltakkal összhangban tételes árazott költségvetés kiállításra, illetve a Megrendelő részére átadásra kerül. A tételes, árazott költségvetésnek alkalmasnak kell lennie a felhívásban rögzített műszaki követelmények, illetve a fajlagos költségkorlátok ellenőrzésére. A Vállakozó vállalja, hogy az energetikai korszerűsítés eredményeként a beruházás megvalósítást megelőző fejlesztés előtti (kiinduló) állapothoz képest az ingatlan elsődleges (primer) energiafogyasztása legalább 30%-os mértékű csökkenést ér el. (Amennyiben a szerződéssel érintett projekt megvalósításában több kivitelező vesz részt, úgy a legalább 30%-os energiamegtakarítás elérése együttes közreműködésükre értendő.) Megrendelő vállalja, hogy a 30%-os mértékű elsődleges (primer) energiafogyasztás csökkenést Hiteles Energetikai Tanúsítvánnyal köteles alátámasztani.
B22: III. Vállalkozási díj:
B23: A Vállalkozó a Lakossági Eljárási Rend alapján benyújtásra kerülő Kölcsönkérelemben foglalt, jelen szerződés II. pontjában részletezett műszaki tartalom szerződésszerű megvalósításának eredményeképpen az alábbi vállalkozói díja összesen:
B24: Nettó: | C24: =SUM(G46:G84)+SUM(I46:I84)+I87 -> 0
B25: + Áfa: | C25: =+C26-C24 -> 0
B26: Bruttó: | C26: =+K88 -> 0
B28: IV. Munkavégzés ütemezése, határidők, fizetési feltételek
B29: Felek rögzítik, hogy a jelen szerződésben foglalt műszaki tartalom megvalósítása (beleértve a beépítésre kerülő anyagok / berendezések beszerzését is), a kapcsolódó Kölcsönkérelem benyújtását megelőzően nem kezdődött meg és a tervezett projektmegvalósítási határidőig megtörténik. A Vállakozó jelen szerződésben foglalt műszaki tartalom megvalósítása kapcsán a Megrendelővel a következőkben állapodik meg:
B31: Munkavégzés megkezdésének várható időpontja (formátum: éééé.hh.)
B32: Munkavégzés befejezésének várható időpontja (formátum: éééé.hh.)
B33: Vállalkozói előlegbekérő/díjbekérő kiállításra kerül (Igen/Nem)
B36: A számlák kiállításakor Vállalkozó vállalja, hogy a Felhívás keretében nem támogatható tevékenységeket külön számlán vagy számlákon szerepelteti. A számla kiállításakor a Vállalkozó vállalja, hogy a számlában foglaltakkal, továbbá a Vállalkozói szerződéssel, illetve annak esetleges módosításaival összhangban tételes, árazott számlarészletező dokumentumot állít ki, illetve ad át a Megrendelő részére, mely dokumentum az elszámolás során becsatolandó. Vállalkozó kijelenti, hogy a Megrendelő nevére szóló jelen szerződésen alapuló számlával vagy számlákkal kapcsolatosan az állami adó- és vámhatóság részére az adatszolgáltatási kötelezettségét az előírt határidőben teljesíti az általános forgalmi adóról szóló 2007. évi CXXVII. törvény 10. számú melléklet 1. pontja szerinti adatszolgáltatási kötelezettségét, amely szerint köteles az állami adó- és vámhatóság részére adatot szolgáltatni a belföldön teljesített termékértékesítéséről, szolgáltatásnyújtásáról kibocsátott vagy kiállított számláról, számlával egy tekintet alá eső okiratról.
B37: V. Jótállási, garanciális, illetve szavatossági kötelezettségek
B38: Vállalkozó vállalja a kapcsolódó jogszabályokban előírt jótállás, garancia, illetve szavatosság nyújtását. Vállalkozó I. osztályú minőség teljesítésére vállalkozik. Kivitelező tudomásul veszi, hogy hibás, nem I. osztályú, jogszabályoknak nem megfelelő teljesítés esetén az átvételre kizárólag a hibák kijavítása után kerülhet sor.
B39: VI. Egyéb rendelkezések
B40: Vállalkozó kijelenti, hogy a. az előzetes felmérés alapján a beruházással érintett épület műszaki állapota alapján alkalmas a jelen szerződésben foglalt munkálatok fogadására; b. a beruházás során kizárólag kereskedelmi forgalomból beszerzett új berendezések, készülékek és anyagok kerültek beépítésére, amelyek rendelkeztek mind a forgalomba hozatali, mind pedig a beépítéshez szükséges engedélyekkel, minősítésekkel, teljesítmény nyilatkozatokkal stb., amelyek meglétéről és azok megfelelő tartalmáról a Kivitelező meggyőződött (figyelemmel a 275/2013. (VII. 16.) Korm. rendelet előírásaira); c. a beruházás az építőipari kivitelezési tevékenységre vonatkozó jogszabályok, szabványok, irányelvek, általános érvényű és eseti előírások, így különösen a statikai, tűzvédelmi és az épületenergetikai követelmények, szakmai, minőségi, környezetvédelmi és biztonsági előírások megtartásával szakszerűen kerül elvégzésre, kiemelve az alábbi jogszabályokat: · a beruházás során alkalmazott műszaki megoldások az épített környezet alakításáról és védelméről szóló 1997. évi LXXVIII. tv. 31. §-a (2) bekezdésének értelmében az országos településrendezési és építési követelményekről szóló kormányrendeletben meghatározott alapvető követelmények érvényre juttatásával valósulnak meg, · a beruházás során alkalmazott műszaki megoldások megfelelnek az Országos Tűzvédelmi Szabályzatról szóló 54/2014. (XII. 5.) BM rendelet előírásainak. A beépítésre kerülő építési termékek tűzállósági teljesítményei megfelelőek; d. a beruházás során a gyártók minősítéseiben és alkalmazástechnikai útmutatóiban foglalt előírások, ajánlások maradéktalanul betartásra kerülnek; e. a beruházás során keletkező építési-bontási hulladék az előírások szerint kerül kezelésre, továbbá az az építőipari kivitelezési tevékenység befejezésekor a munkaterületről a külön jogszabályban foglaltak szerint elszállításra kerül.
B41: Vállalkozó felelős a munkaterület biztonságáért és saját alkalmazottainak munkavédelméért, a saját és a Megrendelő tulajdonának biztonságáért, valamint a Megrendelőnek és harmadik félnek okozott károkért. A munkaterületre szállított anyagok, gépek és egyéb értékek őrzéséről a Vállalkozó gondoskodik. Felek rögzítik, hogy jelen vállalkozási szerződés azon a napon lép hatályba, amelyen a Megrendelő megkötötte a Kölcsönszerződést. A Kölcsönszerződés megkötéséről a Megrendelő haladéktalanul értesíti a Vállalkozót. Felek kijelentik, hogy a Megrendelő sikertelen kölcsönfelvétele esetén egymás felé követelésük nincs; a kölcsönfelvétel meghiúsulásáról a Megrendelő haladéktalanul értesíti a Vállalkozót. Felek rögzítik és kijelentik, hogy „A fenntartható fejlődés elősegítése figyelembe véve az ENSZ fenntartható fejlődésre vonatkozó céljait, a Párizsi Megállapodást, a „szennyező fizet” elvet és a „ne okozz jelentős kárt” elvet.” értelmében a teljes beruházás tervezése és megvalósítása során Felek folyamatosan vizsgálják, hogy annak működése és eredményei hogyan érintik, befolyásolják azt a közösséget és azt a környezetet, amiben a Projekt megvalósul. A környezetvédelmi jogszabályokat Felek betartják, a Projekt által érintett területen a védett természeti és kulturális értékeket megőrzik, a fennálló, vagy a beruházás során keletkezett környezeti kárt és az alapvető jogok tiszteletben tartása szempontjából jogszabályba ütköző nem-megfelelőséget legkésőbb a Projekt megvalósításáig megszüntetik a „Tájékoztató a jelentős károkozás elkerüléséhez - Lakossági energiahatékonysági beruházók részére” című dokumentum, valamint a Lakossági Eljárási Rend Alapjogi Chartának való megfelelésére vonatkozó rendelkezései szerint. A Felek egybehangzóan kijelentik, hogy a Vállalkozó, valamint a Vállalkozó közvetlen vagy közvetett tulajdonosa, vezető tisztségviselője, munkavállalója nem közeli hozzátartozója vagy élettársa a Megrendelőnek, illetve az Otthonfelújítási Programban Adóstársaként megjelölt személynek (továbbiakban: Adóstárs), valamint a Megrendelő, illetve Adóstársa nem munkavállalója, vezető tisztségviselője vagy tagja a Vállalkozónak. Jelen szerződésben nem szabályozott kérdésekben a Polgári Törvénykönyvről szóló 2013. évi V. törvény, valamint a felek külön megállapodása az irányadó.
B43: Műszaki tartalom
B44: Megnevezés | E44: Mennyi-ség | F44: Mérték-egység | G44: Anyagköltség | I44: Munkadíj | K44: Bruttó költség összesen
G45: Nettó | H45: Bruttó | I45: Nettó | J45: Bruttó
B46: B1b. Használati melegvíz rendszerek | C46: Használati melegvíz előállító berendezés | K46: =IFERROR(H46+J46,) -> 0 | L46: =SUM(K46:K49) -> 0
...

Sheet 02_Vállalkozási szerződés2 
B1: Vállalkozási szerződés | K1: Hatályos: | L1: =+'01_Költségvetés'!N3 -> 2025.10.15-től
B2: a KEHOP Plusz-4.1.7-24 kódszámú Otthonfelújítási Program Lakossági energiahatékonysági beruházások megvalósításához igénybevételéhez
B3: amely létrejött egyrészről
B4: név: | E4: {=IF(ISBLANK('01_Költségvetés'!D5:D5),"",'01_Költségvetés'!D5:D5)}
B5: születési hely/idő:
B6: anyja neve:
B7: állandó lakcíme:
B8: (a továbbiakban: Megrendelő), másrészről
B9: cég/vállalkozó neve:
B10: cégjegyzékszám/egyéni vállalkozói nyilvántartási száma:
B11: székhelye:
B12: adószáma:
B13: képviseletében eljáró személy:
B14: mint vállalkozó (a továbbiakban: Vállalkozó),
B15: (a továbbiakban együtt: Felek) között a szerződés aláírásának napján, az alábbiak szerint:
B16: I. A szerződés tárgya:
B17: A „Otthonfelújítási Program - Lakossági energiahatékonysági beruházások megvalósításához” című (KEHOP Plusz 4.1.7-24 kódszámú) Felhíváshoz (a továbbiakban: Felhívás) kapcsolódó Európai Uniós forrású Lakossági Hitelprogramok Eljárási Rendjének (a továbbiakban Lakossági Eljárási Rend) keretében benyújtásra kerülő kölcsönkérelembe foglalt, jelen szerződésben részletezett műszaki tartalom hatályos jogszabályoknak megfelelő módon történő megvalósítása az alábbi ingatlanon:
B18: Az ingatlan címe: | E18: {=IF(ISBLANK('01_Költségvetés'!D6:D6),"",'01_Költségvetés'!D6:D6)}
B20: II. Műszaki tartalom:
B21: Jelen szerződés I. pontjában megjelölt ingatlan vonatkozásában a Megrendelő jelen szerződés alapján megrendeli a Vállalkozótól, a Vállalkozó pedig vállalja – a Lakossági Eljárási Rend alapján benyújtásra kerülő Felhívásban foglalt – a vállalkozói szerződés 1. számú mellékletében felsorolt műszaki tartalom megvalósítását. A Megrendelő kötelezettséget vállal a jelen szerződés alapján elvégzett munka átvételére és a vállalkozói díj megfizetésére. A Vállalkozói szerződés jelen pontjában rögzített táblázatban foglalt műszaki tartalommal, valamint a Lakossági Eljárási Rendben foglaltakkal összhangban tételes árazott költségvetés kiállításra, illetve a Megrendelő részére átadásra kerül. A tételes, árazott költségvetésnek alkalmasnak kell lennie a felhívásban rögzített műszaki követelmények, illetve a fajlagos költségkorlátok ellenőrzésére. A Vállakozó vállalja, hogy az energetikai korszerűsítés eredményeként a beruházás megvalósítást megelőző fejlesztés előtti (kiinduló) állapothoz képest az ingatlan elsődleges (primer) energiafogyasztása legalább 30%-os mértékű csökkenést ér el. (Amennyiben a szerződéssel érintett projekt megvalósításában több kivitelező vesz részt, úgy a legalább 30%-os energiamegtakarítás elérése együttes közreműködésükre értendő.) Megrendelő vállalja, hogy a 30%-os mértékű elsődleges (primer) energiafogyasztás csökkenést Hiteles Energetikai Tanúsítvánnyal köteles alátámasztani.
B22: III. Vállalkozási díj:
B23: A Vállalkozó a Lakossági Eljárási Rend alapján benyújtásra kerülő Kölcsönkérelemben foglalt, jelen szerződés II. pontjában részletezett műszaki tartalom szerződésszerű megvalósításának eredményeképpen az alábbi vállalkozói díja összesen:
B24: Nettó: | C24: =SUM(G47:G85)+SUM(I47:I85)+I88 -> 0
B25: + Áfa: | C25: =+C26-C24 -> 0
B26: Bruttó: | C26: =+K89 -> 0
B28: IV. Munkavégzés ütemezése, határidők, fizetési feltételek
B29: Felek rögzítik, hogy a jelen szerződésben foglalt műszaki tartalom megvalósítása (beleértve a beépítésre kerülő anyagok / berendezések beszerzését is), a kapcsolódó Kölcsönkérelem benyújtását megelőzően nem kezdődött meg és a tervezett projektmegvalósítási határidőig megtörténik. A Vállakozó jelen szerződésben foglalt műszaki tartalom megvalósítása kapcsán a Megrendelővel a következőkben állapodik meg:
B31: Munkavégzés megkezdésének várható időpontja (formátum: éééé.hh.)
B32: Munkavégzés befejezésének várható időpontja (formátum: éééé.hh.)
B33: Vállalkozói előlegbekérő/díjbekérő kiállításra kerül (Igen/Nem)
B36: A számlák kiállításakor Vállalkozó vállalja, hogy a Felhívás keretében nem támogatható tevékenységeket külön számlán vagy számlákon szerepelteti. A számla kiállításakor a Vállalkozó vállalja, hogy a számlában foglaltakkal, továbbá a Vállalkozói szerződéssel, illetve annak esetleges módosításaival összhangban tételes, árazott számlarészletező dokumentumot állít ki, illetve ad át a Megrendelő részére, mely dokumentum az elszámolás során becsatolandó. Vállalkozó kijelenti, hogy a Megrendelő nevére szóló jelen szerződésen alapuló számlával vagy számlákkal kapcsolatosan az állami adó- és vámhatóság részére az adatszolgáltatási kötelezettségét az előírt határidőben teljesíti az általános forgalmi adóról szóló 2007. évi CXXVII. törvény 10. számú melléklet 1. pontja szerinti adatszolgáltatási kötelezettségét, amely szerint köteles az állami adó- és vámhatóság részére adatot szolgáltatni a belföldön teljesített termékértékesítéséről, szolgáltatásnyújtásáról kibocsátott vagy kiállított számláról, számlával egy tekintet alá eső okiratról.
B37: V. Jótállási, garanciális, illetve szavatossági kötelezettségek
B38: Vállalkozó vállalja a kapcsolódó jogszabályokban előírt jótállás, garancia, illetve szavatosság nyújtását. Vállalkozó I. osztályú minőség teljesítésére vállalkozik. Kivitelező tudomásul veszi, hogy hibás, nem I. osztályú, jogszabályoknak nem megfelelő teljesítés esetén az átvételre kizárólag a hibák kijavítása után kerülhet sor.
B39: VI. Egyéb rendelkezések
B40: Vállalkozó kijelenti, hogy a. az előzetes felmérés alapján a beruházással érintett épület műszaki állapota alapján alkalmas a jelen szerződésben foglalt munkálatok fogadására; b. a beruházás során kizárólag kereskedelmi forgalomból beszerzett új berendezések, készülékek és anyagok kerültek beépítésére, amelyek rendelkeztek mind a forgalomba hozatali, mind pedig a beépítéshez szükséges engedélyekkel, minősítésekkel, teljesítmény nyilatkozatokkal stb., amelyek meglétéről és azok megfelelő tartalmáról a Kivitelező meggyőződött (figyelemmel a 275/2013. (VII. 16.) Korm. rendelet előírásaira); c. a beruházás az építőipari kivitelezési tevékenységre vonatkozó jogszabályok, szabványok, irányelvek, általános érvényű és eseti előírások, így különösen a statikai, tűzvédelmi és az épületenergetikai követelmények, szakmai, minőségi, környezetvédelmi és biztonsági előírások megtartásával szakszerűen kerül elvégzésre, kiemelve az alábbi jogszabályokat: · a beruházás során alkalmazott műszaki megoldások az épített környezet alakításáról és védelméről szóló 1997. évi LXXVIII. tv. 31. §-a (2) bekezdésének értelmében az országos településrendezési és építési követelményekről szóló kormányrendeletben meghatározott alapvető követelmények érvényre juttatásával valósulnak meg, · a beruházás során alkalmazott műszaki megoldások megfelelnek az Országos Tűzvédelmi Szabályzatról szóló 54/2014. (XII. 5.) BM rendelet előírásainak. A beépítésre kerülő építési termékek tűzállósági teljesítményei megfelelőek; d. a beruházás során a gyártók minősítéseiben és alkalmazástechnikai útmutatóiban foglalt előírások, ajánlások maradéktalanul betartásra kerülnek; e. a beruházás során keletkező építési-bontási hulladék az előírások szerint kerül kezelésre, továbbá az az építőipari kivitelezési tevékenység befejezésekor a munkaterületről a külön jogszabályban foglaltak szerint elszállításra kerül.
B41: Vállalkozó felelős a munkaterület biztonságáért és saját alkalmazottainak munkavédelméért, a saját és a Megrendelő tulajdonának biztonságáért, valamint a Megrendelőnek és harmadik félnek okozott károkért. A munkaterületre szállított anyagok, gépek és egyéb értékek őrzéséről a Vállalkozó gondoskodik. Felek rögzítik, hogy jelen vállalkozási szerződés azon a napon lép hatályba, amelyen a Megrendelő megkötötte a Kölcsönszerződést. A Kölcsönszerződés megkötéséről a Megrendelő haladéktalanul értesíti a Vállalkozót. Felek kijelentik, hogy a Megrendelő sikertelen kölcsönfelvétele esetén egymás felé követelésük nincs; a kölcsönfelvétel meghiúsulásáról a Megrendelő haladéktalanul értesíti a Vállalkozót. Felek rögzítik és kijelentik, hogy „A fenntartható fejlődés elősegítése figyelembe véve az ENSZ fenntartható fejlődésre vonatkozó céljait, a Párizsi Megállapodást, a „szennyező fizet” elvet és a „ne okozz jelentős kárt” elvet.” értelmében a teljes beruházás tervezése és megvalósítása során Felek folyamatosan vizsgálják, hogy annak működése és eredményei hogyan érintik, befolyásolják azt a közösséget és azt a környezetet, amiben a Projekt megvalósul. A környezetvédelmi jogszabályokat Felek betartják, a Projekt által érintett területen a védett természeti és kulturális értékeket megőrzik, a fennálló, vagy a beruházás során keletkezett környezeti kárt és az alapvető jogok tiszteletben tartása szempontjából jogszabályba ütköző nem-megfelelőséget legkésőbb a Projekt megvalósításáig megszüntetik a „Tájékoztató a jelentős károkozás elkerüléséhez - Lakossági energiahatékonysági beruházók részére” című dokumentum, valamint a Lakossági Eljárási Rend Alapjogi Chartának való megfelelésére vonatkozó rendelkezései szerint. A Felek egybehangzóan kijelentik, hogy a Vállalkozó, valamint a Vállalkozó közvetlen vagy közvetett tulajdonosa, vezető tisztségviselője, munkavállalója nem közeli hozzátartozója vagy élettársa a Megrendelőnek, illetve az Otthonfelújítási Programban Adóstársaként megjelölt személynek (továbbiakban: Adóstárs), valamint a Megrendelő, illetve Adóstársa nem munkavállalója, vezető tisztségviselője vagy tagja a Vállalkozónak. Jelen szerződésben nem szabályozott kérdésekben a Polgári Törvénykönyvről szóló 2013. évi V. törvény, valamint a felek külön megállapodása az irányadó.
B44: Műszaki tartalom
B45: Megnevezés | E45: Mennyi-ség | F45: Mérték-egység | G45: Anyagköltség | I45: Munkadíj | K45: Bruttó költség összesen
G46: Nettó | H46: Bruttó | I46: Nettó | J46: Bruttó
B47: B1b. Használati melegvíz rendszerek | C47: Használati melegvíz előállító berendezés | K47: =IFERROR(H47+J47,) -> 0 | L47: =SUM(K47:K50) -> 0
...

Sheet 02_Vállalkozási szerződés3
B1: Vállalkozási szerződés | K1: Hatályos: | L1: =+'01_Költségvetés'!N3 -> 2025.10.15-től
B2: a KEHOP Plusz-4.1.7-24 kódszámú Otthonfelújítási Program Lakossági energiahatékonysági beruházások megvalósításához igénybevételéhez
B3: amely létrejött egyrészről
B4: név: | E4: {=IF(ISBLANK('01_Költségvetés'!D5:D5),"",'01_Költségvetés'!D5:D5)}
B5: születési hely/idő:
B6: anyja neve:
B7: állandó lakcíme:
B8: (a továbbiakban: Megrendelő), másrészről
B9: cég/vállalkozó neve:
B10: cégjegyzékszám/egyéni vállalkozói nyilvántartási száma:
B11: székhelye:
B12: adószáma:
B13: képviseletében eljáró személy:
B14: mint vállalkozó (a továbbiakban: Vállalkozó),
B15: (a továbbiakban együtt: Felek) között a szerződés aláírásának napján, az alábbiak szerint:
B16: I. A szerződés tárgya:
B17: A „Otthonfelújítási Program - Lakossági energiahatékonysági beruházások megvalósításához” című (KEHOP Plusz 4.1.7-24 kódszámú) Felhíváshoz (a továbbiakban: Felhívás) kapcsolódó Európai Uniós forrású Lakossági Hitelprogramok Eljárási Rendjének (a továbbiakban Lakossági Eljárási Rend) keretében benyújtásra kerülő kölcsönkérelembe foglalt, jelen szerződésben részletezett műszaki tartalom hatályos jogszabályoknak megfelelő módon történő megvalósítása az alábbi ingatlanon:
B18: Az ingatlan címe: | E18: {=IF(ISBLANK('01_Költségvetés'!D6:D6),"",'01_Költségvetés'!D6:D6)}
B20: II. Műszaki tartalom:
B21: Jelen szerződés I. pontjában megjelölt ingatlan vonatkozásában a Megrendelő jelen szerződés alapján megrendeli a Vállalkozótól, a Vállalkozó pedig vállalja – a Lakossági Eljárási Rend alapján benyújtásra kerülő Felhívásban foglalt – a vállalkozói szerződés 1. számú mellékletében felsorolt műszaki tartalom megvalósítását. A Megrendelő kötelezettséget vállal a jelen szerződés alapján elvégzett munka átvételére és a vállalkozói díj megfizetésére. A Vállalkozói szerződés jelen pontjában rögzített táblázatban foglalt műszaki tartalommal, valamint a Lakossági Eljárási Rendben foglaltakkal összhangban tételes árazott költségvetés kiállításra, illetve a Megrendelő részére átadásra kerül. A tételes, árazott költségvetésnek alkalmasnak kell lennie a felhívásban rögzített műszaki követelmények, illetve a fajlagos költségkorlátok ellenőrzésére. A Vállakozó vállalja, hogy az energetikai korszerűsítés eredményeként a beruházás megvalósítást megelőző fejlesztés előtti (kiinduló) állapothoz képest az ingatlan elsődleges (primer) energiafogyasztása legalább 30%-os mértékű csökkenést ér el. (Amennyiben a szerződéssel érintett projekt megvalósításában több kivitelező vesz részt, úgy a legalább 30%-os energiamegtakarítás elérése együttes közreműködésükre értendő.) Megrendelő vállalja, hogy a 30%-os mértékű elsődleges (primer) energiafogyasztás csökkenést Hiteles Energetikai Tanúsítvánnyal köteles alátámasztani.
B22: III. Vállalkozási díj:
B23: A Vállalkozó a Lakossági Eljárási Rend alapján benyújtásra kerülő Kölcsönkérelemben foglalt, jelen szerződés II. pontjában részletezett műszaki tartalom szerződésszerű megvalósításának eredményeképpen az alábbi vállalkozói díja összesen:
B24: Nettó: | C24: =SUM(G47:G85)+SUM(I47:I85)+I88 -> 0
B25: + Áfa: | C25: =+C26-C24 -> 0
B26: Bruttó: | C26: =+K89 -> 0
B28: IV. Munkavégzés ütemezése, határidők, fizetési feltételek
B29: Felek rögzítik, hogy a jelen szerződésben foglalt műszaki tartalom megvalósítása (beleértve a beépítésre kerülő anyagok / berendezések beszerzését is), a kapcsolódó Kölcsönkérelem benyújtását megelőzően nem kezdődött meg és a tervezett projektmegvalósítási határidőig megtörténik. A Vállakozó jelen szerződésben foglalt műszaki tartalom megvalósítása kapcsán a Megrendelővel a következőkben állapodik meg:
B31: Munkavégzés megkezdésének várható időpontja (formátum: éééé.hh.)
B32: Munkavégzés befejezésének várható időpontja (formátum: éééé.hh.)
B33: Vállalkozói előlegbekérő/díjbekérő kiállításra kerül (Igen/Nem)
B36: A számlák kiállításakor Vállalkozó vállalja, hogy a Felhívás keretében nem támogatható tevékenységeket külön számlán vagy számlákon szerepelteti. A számla kiállításakor a Vállalkozó vállalja, hogy a számlában foglaltakkal, továbbá a Vállalkozói szerződéssel, illetve annak esetleges módosításaival összhangban tételes, árazott számlarészletező dokumentumot állít ki, illetve ad át a Megrendelő részére, mely dokumentum az elszámolás során becsatolandó. Vállalkozó kijelenti, hogy a Megrendelő nevére szóló jelen szerződésen alapuló számlával vagy számlákkal kapcsolatosan az állami adó- és vámhatóság részére az adatszolgáltatási kötelezettségét az előírt határidőben teljesíti az általános forgalmi adóról szóló 2007. évi CXXVII. törvény 10. számú melléklet 1. pontja szerinti adatszolgáltatási kötelezettségét, amely szerint köteles az állami adó- és vámhatóság részére adatot szolgáltatni a belföldön teljesített termékértékesítéséről, szolgáltatásnyújtásáról kibocsátott vagy kiállított számláról, számlával egy tekintet alá eső okiratról.
B37: V. Jótállási, garanciális, illetve szavatossági kötelezettségek
